Workbook

Sheet Raw Results
A1: Location Code | B1: Depth | C1: Sampled Date | D1: Chem Name | E1: Prefix | F1: Result | G1: Unit
A2: BH01 | B2: 3 - 3.1 | C2: 45245.625 | D2: Arsenic | F2: 45 | G2: mg/kg
A3: BH01 | B3: 3 - 3.1 | C3: 45245.625 | D3: Cadmium | F3: 24 | G3: mg/kg
A4: BH01 | B4: 3 - 3.1 | C4: 45245.625 | D4: Chromium | F4: 615 | G4: mg/kg
A5: BH01 | B5: 3 - 3.1 | C5: 45245.625 | D5: Copper | F5: 253 | G5: mg/kg
A6: BH01 | B6: 3 - 3.1 | C6: 45245.625 | D6: Lead | F6: 1800 | G6: mg/kg
A7: BH01 | B7: 3 - 3.1 | C7: 45245.625 | D7: Mercury | F7: 0.1 | G7: mg/kg
A8: BH01 | B8: 3 - 3.1 | C8: 45245.625 | D8: Nickel | F8: 694 | G8: mg/kg
A9: BH01 | B9: 3 - 3.1 | C9: 45245.625 | D9: Zinc | F9: 2340 | G9: mg/kg
A10: BH01 | B10: 4.8 - 4.9 | C10: 45245.625 | D10: Arsenic | F10: 26 | G10: mg/kg
A11: BH01 | B11: 4.8 - 4.9 | C11: 45245.625 | D11: Cadmium | F11: 5 | G11: mg/kg
A12: BH01 | B12: 4.8 - 4.9 | C12: 45245.625 | D12: Chromium | F12: 50 | G12: mg/kg
A13: BH01 | B13: 4.8 - 4.9 | C13: 45245.625 | D13: Copper | F13: 2150 | G13: mg/kg
... A18: BH03 | B18: 0.5 - 0.6 | C18: 45245.625 | D18: Arsenic | F18: 11 | G18: mg/kg
A19: BH03 | B19: 0.5 - 0.6 | C19: 45245.625 | D19: Cadmium | E19: < | F19: 1 | G19: mg/kg
A20: BH03 | B20: 0.5 - 0.6 | C20: 45245.625 | D20: Chromium | F20: 42 | G20: mg/kg
A21: BH03 | B21: 0.5 - 0.6 | C21: 45245.625 | D21: Copper | F21: 23 | G21: mg/kg
A22: BH03 | B22: 0.5 - 0.6 | C22: 45245.625 | D22: Lead | F22: 22 | G22: mg/kg
A23: BH03 | B23: 0.5 - 0.6 | C23: 45245.625 | D23: Mercury | E23: < | F23: 0.1 | G23: mg/kg
A24: BH03 | B24: 0.5 - 0.6 | C24: 45245.625 | D24: Nickel | F24: 37 | G24: mg/kg
A25: BH03 | B25: 0.5 - 0.6 | C25: 45245.625 | D25: Zinc | F25: 72 | G25: mg/kg
A26: BH03 | B26: 2 - 2.1 | C26: 45245.625 | D26: Arsenic | F26: 6 | G26: mg/kg
A27: BH03 | B27: 2 - 2.1 | C27: 45245.625 | D27: Cadmium | E27: < | F27: 1 | G27: mg/kg
A28: BH03 | B28: 2 - 2.1 | C28: 45245.625 | D28: Chromium | F28: 28 | G28: mg/kg
A29: BH03 | B29: 2 - 2.1 | C29: 45245.625 | D29: Copper | F29: 49 | G29: mg/kg
A30: BH03 | B30: 2 - 2.1 | C30: 45245.625 | D30: Lead | F30: 184 | G30: mg/kg
A31: BH03 | B31: 2 - 2.1 | C31: 45245.625 | D31: Mercury | E31: < | F31: 0.1 | G31: mg/kg
A32: BH03 | B32: 2 - 2.1 | C32: 45245.625 | D32: Nickel | F32: 26 | G32: mg/kg
A33: BH03 | B33: 2 - 2.1 | C33: 45245.625 | D33: Zinc | F33: 225 | G33: mg/kg
A34: BH05 | B34: 1.8 - 1.9 | C34: 45245.625 | D34: Arsenic | F34: 5 | G34: mg/kg
A35: BH05 | B35: 1.8 - 1.9 | C35: 45245.625 | D35: Cadmium | E35: < | F35: 1 | G35: mg/kg
A36: BH05 | B36: 1.8 - 1.9 | C36: 45245.625 | D36: Chromium | F36: 56 | G36: mg/kg
A37: BH05 | B37: 1.8 - 1.9 | C37: 45245.625 | D37: Copper | F37: 22 | G37: mg/kg
A38: BH05 | B38: 1.8 - 1.9 | C38: 45245.625 | D38: Lead | F38: 26 | G38: mg/kg
A39: BH05 | B39: 1.8 - 1.9 | C39: 45245.625 | D39: Mercury | E39: < | F39: 0.1 | G39: mg/kg
A40: BH05 | B40: 1.8 - 1.9 | C40: 45245.625 | D40: Nickel | F40: 55 | G40: mg/kg
A41: BH05 | B41: 1.8 - 1.9 | C41: 45245.625 | D41: Zinc | F41: 344 | G41: mg/kg
A42: BH05 | B42: 5 - 5.1 | C42: 45245.625 | D42: Arsenic | F42: 12 | G42: mg/kg
A43: BH05 | B43: 5 - 5.1 | C43: 45245.625 | D43: Cadmium | F43: 2 | G43: mg/kg
A44: BH05 | B44: 5 - 5.1 | C44: 45245.625 | D44: Chromium | F44: 34 | G44: mg/kg
...

Sheet Criteria
A1: Chem Name | B1: Action Level
A2: Lead | B2: 300 mg/kg
A3: Mercury | B3: 40 mg/kg
A4: Nickel | B4: 400 mg/kg
A5: Arsenic | B5: 100 mg/kg
A6: Cadmium | B6: 20 mg/kg
A7: Chromium (total) | B7: 100 mg/kg
A8: Copper | B8: 6000 mg/kg
A9: Zinc | B9: 7400 mg/kg

Sheet Exceeds
A1: Location Code | B1: Depth | C1: Sampled Date | D1: Chem Name | E1: Prefix | F1: Result | G1: Unit | H1: Criteria Formula 1 | I1: Criteria Formula 2
A2: BH01 | B2: 3 - 3.1 | C2: 45245.625 | D2: Arsenic | F2: 45 | G2: mg/kg | H2: =IF( IF(E2="<",F2/2,F2) > VALUE(LEFT(_xlfn.XLOOKUP(D2,Criteria!A:A,Criteria!B:B),FIND(" ",_xlfn.XLOOKUP(D2,Criteria!A:A,Criteria!B:B))-1)), "Exceeds", "OK" ) -> OK | I2: =IFERROR( _xlfn.LET( _xlpm.chem, D2, _xlpm.prefix, E2, _xlpm.result, F2, _xlpm.mappedChem, _xlfn.XLOOKUP(_xlpm.chem, Map!A:A, Map!B:B), _xlpm.critText, _xlfn.XLOOKUP(_xlpm.mappedChem, Criteria!A:A, Criteria!B:B), _xlpm.critValue, VALUE(LEFT(_xlpm.critText, FIND(" ", _xlpm.critText)-1)), _xlpm.adjResult, IF(_xlpm.prefix="<", _xlpm.result/2, _xlpm.result), IF(_xlpm.adjResult > _xlpm.critValue, "Exceeds", "OK") ), "NOT FOUND") -> OK
A3: BH01 | B3: 3 - 3.1 | C3: 45245.625 | D3: Cadmium | F3: 24 | G3: mg/kg | H3: =IF( IF(E3="<",F3/2,F3) > VALUE(LEFT(_xlfn.XLOOKUP(D3,Criteria!A:A,Criteria!B:B),FIND(" ",_xlfn.XLOOKUP(D3,Criteria!A:A,Criteria!B:B))-1)), "Exceeds", "OK" ) -> Exceeds | I3: =IFERROR( _xlfn.LET( _xlpm.chem, D3, _xlpm.prefix, E3, _xlpm.result, F3, _xlpm.mappedChem, _xlfn.XLOOKUP(_xlpm.chem, Map!A:A, Map!B:B), _xlpm.critText, _xlfn.XLOOKUP(_xlpm.mappedChem, Criteria!A:A, Criteria!B:B), _xlpm.critValue, VALUE(LEFT(_xlpm.critText, FIND(" ", _xlpm.critText)-1)), _xlpm.adjResult, IF(_xlpm.prefix="<", _xlpm.result/2, _xlpm.result), IF(_xlpm.adjResult > _xlpm.critValue, "Exceeds", "OK") ), "NOT FOUND") -> Exceeds
A4: BH01 | B4: 3 - 3.1 | C4: 45245.625 | D4: Chromium | F4: 615 | G4: mg/kg | H4: =IF( IF(E4="<",F4/2,F4) > VALUE(LEFT(_xlfn.XLOOKUP(D4,Criteria!A:A,Criteria!B:B),FIND(" ",_xlfn.XLOOKUP(D4,Criteria!A:A,Criteria!B:B))-1)), "Exceeds", "OK" ) -> #N/A | I4: =IFERROR( _xlfn.LET( _xlpm.chem, D4, _xlpm.prefix, E4, _xlpm.result, F4, _xlpm.mappedChem, _xlfn.XLOOKUP(_xlpm.chem, Map!A:A, Map!B:B), _xlpm.critText, _xlfn.XLOOKUP(_xlpm.mappedChem, Criteria!A:A, Criteria!B:B), _xlpm.critValue, VALUE(LEFT(_xlpm.critText, FIND(" ", _xlpm.critText)-1)), _xlpm.adjResult, IF(_xlpm.prefix="<", _xlpm.result/2, _xlpm.result), IF(_xlpm.adjResult > _xlpm.critValue, "Exceeds", "OK") ), "NOT FOUND") -> Exceeds
A5: BH01 | B5: 3 - 3.1 | C5: 45245.625 | D5: Copper | F5: 253 | G5: mg/kg | H5: =IF( IF(E5="<",F5/2,F5) > VALUE(LEFT(_xlfn.XLOOKUP(D5,Criteria!A:A,Criteria!B:B),FIND(" ",_xlfn.XLOOKUP(D5,Criteria!A:A,Criteria!B:B))-1)), "Exceeds", "OK" ) -> OK | I5: =IFERROR( _xlfn.LET( _xlpm.chem, D5, _xlpm.prefix, E5, _xlpm.result, F5, _xlpm.mappedChem, _xlfn.XLOOKUP(_xlpm.chem, Map!A:A, Map!B:B), _xlpm.critText, _xlfn.XLOOKUP(_xlpm.mappedChem, Criteria!A:A, Criteria!B:B), _xlpm.critValue, VALUE(LEFT(_xlpm.critText, FIND(" ", _xlpm.critText)-1)), _xlpm.adjResult, IF(_xlpm.prefix="<", _xlpm.result/2, _xlpm.result), IF(_xlpm.adjResult > _xlpm.critValue, "Exceeds", "OK") ), "NOT FOUND") -> OK
A6: BH01 | B6: 3 - 3.1 | C6: 45245.625 | D6: Lead | F6: 1800 | G6: mg/kg | H6: =IF( IF(E6="<",F6/2,F6) > VALUE(LEFT(_xlfn.XLOOKUP(D6,Criteria!A:A,Criteria!B:B),FIND(" ",_xlfn.XLOOKUP(D6,Criteria!A:A,Criteria!B:B))-1)), "Exceeds", "OK" ) -> Exceeds | I6: =IFERROR( _xlfn.LET( _xlpm.chem, D6, _xlpm.prefix, E6, _xlpm.result, F6, _xlpm.mappedChem, _xlfn.XLOOKUP(_xlpm.chem, Map!A:A, Map!B:B), _xlpm.critText, _xlfn.XLOOKUP(_xlpm.mappedChem, Criteria!A:A, Criteria!B:B), _xlpm.critValue, VALUE(LEFT(_xlpm.critText, FIND(" ", _xlpm.critText)-1)), _xlpm.adjResult, IF(_xlpm.prefix="<", _xlpm.result/2, _xlpm.result), IF(_xlpm.adjResult > _xlpm.critValue, "Exceeds", "OK") ), "NOT FOUND") -> Exceeds
A7: BH01 | B7: 3 - 3.1 | C7: 45245.625 | D7: Mercury | F7: 0.1 | G7: mg/kg | H7: =IF( IF(E7="<",F7/2,F7) > VALUE(LEFT(_xlfn.XLOOKUP(D7,Criteria!A:A,Criteria!B:B),FIND(" ",_xlfn.XLOOKUP(D7,Criteria!A:A,Criteria!B:B))-1)), "Exceeds", "OK" ) -> OK | I7: =IFERROR( _xlfn.LET( _xlpm.chem, D7, _xlpm.prefix, E7, _xlpm.result, F7, _xlpm.mappedChem, _xlfn.XLOOKUP(_xlpm.chem, Map!A:A, Map!B:B), _xlpm.critText, _xlfn.XLOOKUP(_xlpm.mappedChem, Criteria!A:A, Criteria!B:B), _xlpm.critValue, VALUE(LEFT(_xlpm.critText, FIND(" ", _xlpm.critText)-1)), _xlpm.adjResult, IF(_xlpm.prefix="<", _xlpm.result/2, _xlpm.result), IF(_xlpm.adjResult > _xlpm.critValue, "Exceeds", "OK") ), "NOT FOUND") -> OK
A8: BH01 | B8: 3 - 3.1 | C8: 45245.625 | D8: Nickel | F8: 694 | G8: mg/kg | H8: =IF( IF(E8="<",F8/2,F8) > VALUE(LEFT(_xlfn.XLOOKUP(D8,Criteria!A:A,Criteria!B:B),FIND(" ",_xlfn.XLOOKUP(D8,Criteria!A:A,Criteria!B:B))-1)), "Exceeds", "OK" ) -> Exceeds | I8: =IFERROR( _xlfn.LET( _xlpm.chem, D8, _xlpm.prefix, E8, _xlpm.result, F8, _xlpm.mappedChem, _xlfn.XLOOKUP(_xlpm.chem, Map!A:A, Map!B:B), _xlpm.critText, _xlfn.XLOOKUP(_xlpm.mappedChem, Criteria!A:A, Criteria!B:B), _xlpm.critValue, VALUE(LEFT(_xlpm.critText, FIND(" ", _xlpm.critText)-1)), _xlpm.adjResult, IF(_xlpm.prefix="<", _xlpm.result/2, _xlpm.result), IF(_xlpm.adjResult > _xlpm.critValue, "Exceeds", "OK") ), "NOT FOUND") -> Exceeds
A9: BH01 | B9: 3 - 3.1 | C9: 45245.625 | D9: Zinc | F9: 2340 | G9: mg/kg | H9: =IF( IF(E9="<",F9/2,F9) > VALUE(LEFT(_xlfn.XLOOKUP(D9,Criteria!A:A,Criteria!B:B),FIND(" ",_xlfn.XLOOKUP(D9,Criteria!A:A,Criteria!B:B))-1)), "Exceeds", "OK" ) -> OK | I9: =IFERROR( _xlfn.LET( _xlpm.chem, D9, _xlpm.prefix, E9, _xlpm.result, F9, _xlpm.mappedChem, _xlfn.XLOOKUP(_xlpm.chem, Map!A:A, Map!B:B), _xlpm.critText, _xlfn.XLOOKUP(_xlpm.mappedChem, Criteria!A:A, Criteria!B:B), _xlpm.critValue, VALUE(LEFT(_xlpm.critText, FIND(" ", _xlpm.critText)-1)), _xlpm.adjResult, IF(_xlpm.prefix="<", _xlpm.result/2, _xlpm.result), IF(_xlpm.adjResult > _xlpm.critValue, "Exceeds", "OK") ), "NOT FOUND") -> OK
A10: BH01 | B10: 4.8 - 4.9 | C10: 45245.625 | D10: Arsenic | F10: 26 | G10: mg/kg | H10: =IF( IF(E10="<",F10/2,F10) > VALUE(LEFT(_xlfn.XLOOKUP(D10,Criteria!A:A,Criteria!B:B),FIND(" ",_xlfn.XLOOKUP(D10,Criteria!A:A,Criteria!B:B))-1)), "Exceeds", "OK" ) -> OK | I10: =IFERROR( _xlfn.LET( _xlpm.chem, D10, _xlpm.prefix, E10, _xlpm.result, F10, _xlpm.mappedChem, _xlfn.XLOOKUP(_xlpm.chem, Map!A:A, Map!B:B), _xlpm.critText, _xlfn.XLOOKUP(_xlpm.mappedChem, Criteria!A:A, Criteria!B:B), _xlpm.critValue, VALUE(LEFT(_xlpm.critText, FIND(" ", _xlpm.critText)-1)), _xlpm.adjResult, IF(_xlpm.prefix="<", _xlpm.result/2, _xlpm.result), IF(_xlpm.adjResult > _xlpm.critValue, "Exceeds", "OK") ), "NOT FOUND") -> OK
A11: BH01 | B11: 4.8 - 4.9 | C11: 45245.625 | D11: Cadmium | F11: 5 | G11: mg/kg | H11: =IF( IF(E11="<",F11/2,F11) > VALUE(LEFT(_xlfn.XLOOKUP(D11,Criteria!A:A,Criteria!B:B),FIND(" ",_xlfn.XLOOKUP(D11,Criteria!A:A,Criteria!B:B))-1)), "Exceeds", "OK" ) -> OK | I11: =IFERROR( _xlfn.LET( _xlpm.chem, D11, _xlpm.prefix, E11, _xlpm.result, F11, _xlpm.mappedChem, _xlfn.XLOOKUP(_xlpm.chem, Map!A:A, Map!B:B), _xlpm.critText, _xlfn.XLOOKUP(_xlpm.mappedChem, Criteria!A:A, Criteria!B:B), _xlpm.critValue, VALUE(LEFT(_xlpm.critText, FIND(" ", _xlpm.critText)-1)), _xlpm.adjResult, IF(_xlpm.prefix="<", _xlpm.result/2, _xlpm.result), IF(_xlpm.adjResult > _xlpm.critValue, "Exceeds", "OK") ), "NOT FOUND") -> OK
A12: BH01 | B12: 4.8 - 4.9 | C12: 45245.625 | D12: Chromium | F12: 50 | G12: mg/kg | H12: =IF( IF(E12="<",F12/2,F12) > VALUE(LEFT(_xlfn.XLOOKUP(D12,Criteria!A:A,Criteria!B:B),FIND(" ",_xlfn.XLOOKUP(D12,Criteria!A:A,Criteria!B:B))-1)), "Exceeds", "OK" ) -> #N/A | I12: =IFERROR( _xlfn.LET( _xlpm.chem, D12, _xlpm.prefix, E12, _xlpm.result, F12, _xlpm.mappedChem, _xlfn.XLOOKUP(_xlpm.chem, Map!A:A, Map!B:B), _xlpm.critText, _xlfn.XLOOKUP(_xlpm.mappedChem, Criteria!A:A, Criteria!B:B), _xlpm.critValue, VALUE(LEFT(_xlpm.critText, FIND(" ", _xlpm.critText)-1)), _xlpm.adjResult, IF(_xlpm.prefix="<", _xlpm.result/2, _xlpm.result), IF(_xlpm.adjResult > _xlpm.critValue, "Exceeds", "OK") ), "NOT FOUND") -> OK
A13: BH01 | B13: 4.8 - 4.9 | C13: 45245.625 | D13: Copper | F13: 2150 | G13: mg/kg | H13: =IF( IF(E13="<",F13/2,F13) > VALUE(LEFT(_xlfn.XLOOKUP(D13,Criteria!A:A,Criteria!B:B),FIND(" ",_xlfn.XLOOKUP(D13,Criteria!A:A,Criteria!B:B))-1)), "Exceeds", "OK" ) -> OK | I13: =IFERROR( _xlfn.LET( _xlpm.chem, D13, _xlpm.prefix, E13, _xlpm.result, F13, _xlpm.mappedChem, _xlfn.XLOOKUP(_xlpm.chem, Map!A:A, Map!B:B), _xlpm.critText, _xlfn.XLOOKUP(_xlpm.mappedChem, Criteria!A:A, Criteria!B:B), _xlpm.critValue, VALUE(LEFT(_xlpm.critText, FIND(" ", _xlpm.critText)-1)), _xlpm.adjResult, IF(_xlpm.prefix="<", _xlpm.result/2, _xlpm.result), IF(_xlpm.adjResult > _xlpm.critValue, "Exceeds", "OK") ), "NOT FOUND") -> OK
... A18: BH03 | B18: 0.5 - 0.6 | C18: 45245.625 | D18: Arsenic | F18: 11 | G18: mg/kg | H18: =IF( IF(E18="<",F18/2,F18) > VALUE(LEFT(_xlfn.XLOOKUP(D18,Criteria!A:A,Criteria!B:B),FIND(" ",_xlfn.XLOOKUP(D18,Criteria!A:A,Criteria!B:B))-1)), "Exceeds", "OK" ) -> OK | I18: =IFERROR( _xlfn.LET( _xlpm.chem, D18, _xlpm.prefix, E18, _xlpm.result, F18, _xlpm.mappedChem, _xlfn.XLOOKUP(_xlpm.chem, Map!A:A, Map!B:B), _xlpm.critText, _xlfn.XLOOKUP(_xlpm.mappedChem, Criteria!A:A, Criteria!B:B), _xlpm.critValue, VALUE(LEFT(_xlpm.critText, FIND(" ", _xlpm.critText)-1)), _xlpm.adjResult, IF(_xlpm.prefix="<", _xlpm.result/2, _xlpm.result), IF(_xlpm.adjResult > _xlpm.critValue, "Exceeds", "OK") ), "NOT FOUND") -> OK
A19: BH03 | B19: 0.5 - 0.6 | C19: 45245.625 | D19: Cadmium | E19: < | F19: 1 | G19: mg/kg | H19: =IF( IF(E19="<",F19/2,F19) > VALUE(LEFT(_xlfn.XLOOKUP(D19,Criteria!A:A,Criteria!B:B),FIND(" ",_xlfn.XLOOKUP(D19,Criteria!A:A,Criteria!B:B))-1)), "Exceeds", "OK" ) -> OK | I19: =IFERROR( _xlfn.LET( _xlpm.chem, D19, _xlpm.prefix, E19, _xlpm.result, F19, _xlpm.mappedChem, _xlfn.XLOOKUP(_xlpm.chem, Map!A:A, Map!B:B), _xlpm.critText, _xlfn.XLOOKUP(_xlpm.mappedChem, Criteria!A:A, Criteria!B:B), _xlpm.critValue, VALUE(LEFT(_xlpm.critText, FIND(" ", _xlpm.critText)-1)), _xlpm.adjResult, IF(_xlpm.prefix="<", _xlpm.result/2, _xlpm.result), IF(_xlpm.adjResult > _xlpm.critValue, "Exceeds", "OK") ), "NOT FOUND") -> OK
A20: BH03 | B20: 0.5 - 0.6 | C20: 45245.625 | D20: Chromium | F20: 42 | G20: mg/kg | H20: =IF( IF(E20="<",F20/2,F20) > VALUE(LEFT(_xlfn.XLOOKUP(D20,Criteria!A:A,Criteria!B:B),FIND(" ",_xlfn.XLOOKUP(D20,Criteria!A:A,Criteria!B:B))-1)), "Exceeds", "OK" ) -> #N/A | I20: =IFERROR( _xlfn.LET( _xlpm.chem, D20, _xlpm.prefix, E20, _xlpm.result, F20, _xlpm.mappedChem, _xlfn.XLOOKUP(_xlpm.chem, Map!A:A, Map!B:B), _xlpm.critText, _xlfn.XLOOKUP(_xlpm.mappedChem, Criteria!A:A, Criteria!B:B), _xlpm.critValue, VALUE(LEFT(_xlpm.critText, FIND(" ", _xlpm.critText)-1)), _xlpm.adjResult, IF(_xlpm.prefix="<", _xlpm.result/2, _xlpm.result), IF(_xlpm.adjResult > _xlpm.critValue, "Exceeds", "OK") ), "NOT FOUND") -> OK
A21: BH03 | B21: 0.5 - 0.6 | C21: 45245.625 | D21: Copper | F21: 23 | G21: mg/kg | H21: =IF( IF(E21="<",F21/2,F21) > VALUE(LEFT(_xlfn.XLOOKUP(D21,Criteria!A:A,Criteria!B:B),FIND(" ",_xlfn.XLOOKUP(D21,Criteria!A:A,Criteria!B:B))-1)), "Exceeds", "OK" ) -> OK | I21: =IFERROR( _xlfn.LET( _xlpm.chem, D21, _xlpm.prefix, E21, _xlpm.result, F21, _xlpm.mappedChem, _xlfn.XLOOKUP(_xlpm.chem, Map!A:A, Map!B:B), _xlpm.critText, _xlfn.XLOOKUP(_xlpm.mappedChem, Criteria!A:A, Criteria!B:B), _xlpm.critValue, VALUE(LEFT(_xlpm.critText, FIND(" ", _xlpm.critText)-1)), _xlpm.adjResult, IF(_xlpm.prefix="<", _xlpm.result/2, _xlpm.result), IF(_xlpm.adjResult > _xlpm.critValue, "Exceeds", "OK") ), "NOT FOUND") -> OK
A22: BH03 | B22: 0.5 - 0.6 | C22: 45245.625 | D22: Lead | F22: 22 | G22: mg/kg | H22: =IF( IF(E22="<",F22/2,F22) > VALUE(LEFT(_xlfn.XLOOKUP(D22,Criteria!A:A,Criteria!B:B),FIND(" ",_xlfn.XLOOKUP(D22,Criteria!A:A,Criteria!B:B))-1)), "Exceeds", "OK" ) -> OK | I22: =IFERROR( _xlfn.LET( _xlpm.chem, D22, _xlpm.prefix, E22, _xlpm.result, F22, _xlpm.mappedChem, _xlfn.XLOOKUP(_xlpm.chem, Map!A:A, Map!B:B), _xlpm.critText, _xlfn.XLOOKUP(_xlpm.mappedChem, Criteria!A:A, Criteria!B:B), _xlpm.critValue, VALUE(LEFT(_xlpm.critText, FIND(" ", _xlpm.critText)-1)), _xlpm.adjResult, IF(_xlpm.prefix="<", _xlpm.result/2, _xlpm.result), IF(_xlpm.adjResult > _xlpm.critValue, "Exceeds", "OK") ), "NOT FOUND") -> OK
A23: BH03 | B23: 0.5 - 0.6 | C23: 45245.625 | D23: Mercury | E23: < | F23: 0.1 | G23: mg/kg | H23: =IF( IF(E23="<",F23/2,F23) > VALUE(LEFT(_xlfn.XLOOKUP(D23,Criteria!A:A,Criteria!B:B),FIND(" ",_xlfn.XLOOKUP(D23,Criteria!A:A,Criteria!B:B))-1)), "Exceeds", "OK" ) -> OK | I23: =IFERROR( _xlfn.LET( _xlpm.chem, D23, _xlpm.prefix, E23, _xlpm.result, F23, _xlpm.mappedChem, _xlfn.XLOOKUP(_xlpm.chem, Map!A:A, Map!B:B), _xlpm.critText, _xlfn.XLOOKUP(_xlpm.mappedChem, Criteria!A:A, Criteria!B:B), _xlpm.critValue, VALUE(LEFT(_xlpm.critText, FIND(" ", _xlpm.critText)-1)), _xlpm.adjResult, IF(_xlpm.prefix="<", _xlpm.result/2, _xlpm.result), IF(_xlpm.adjResult > _xlpm.critValue, "Exceeds", "OK") ), "NOT FOUND") -> OK
A24: BH03 | B24: 0.5 - 0.6 | C24: 45245.625 | D24: Nickel | F24: 37 | G24: mg/kg | H24: =IF( IF(E24="<",F24/2,F24) > VALUE(LEFT(_xlfn.XLOOKUP(D24,Criteria!A:A,Criteria!B:B),FIND(" ",_xlfn.XLOOKUP(D24,Criteria!A:A,Criteria!B:B))-1)), "Exceeds", "OK" ) -> OK | I24: =IFERROR( _xlfn.LET( _xlpm.chem, D24, _xlpm.prefix, E24, _xlpm.result, F24, _xlpm.mappedChem, _xlfn.XLOOKUP(_xlpm.chem, Map!A:A, Map!B:B), _xlpm.critText, _xlfn.XLOOKUP(_xlpm.mappedChem, Criteria!A:A, Criteria!B:B), _xlpm.critValue, VALUE(LEFT(_xlpm.critText, FIND(" ", _xlpm.critText)-1)), _xlpm.adjResult, IF(_xlpm.prefix="<", _xlpm.result/2, _xlpm.result), IF(_xlpm.adjResult > _xlpm.critValue, "Exceeds", "OK") ), "NOT FOUND") -> OK
A25: BH03 | B25: 0.5 - 0.6 | C25: 45245.625 | D25: Zinc | F25: 72 | G25: mg/kg | H25: =IF( IF(E25="<",F25/2,F25) > VALUE(LEFT(_xlfn.XLOOKUP(D25,Criteria!A:A,Criteria!B:B),FIND(" ",_xlfn.XLOOKUP(D25,Criteria!A:A,Criteria!B:B))-1)), "Exceeds", "OK" ) -> OK | I25: =IFERROR( _xlfn.LET( _xlpm.chem, D25, _xlpm.prefix, E25, _xlpm.result, F25, _xlpm.mappedChem, _xlfn.XLOOKUP(_xlpm.chem, Map!A:A, Map!B:B), _xlpm.critText, _xlfn.XLOOKUP(_xlpm.mappedChem, Criteria!A:A, Criteria!B:B), _xlpm.critValue, VALUE(LEFT(_xlpm.critText, FIND(" ", _xlpm.critText)-1)), _xlpm.adjResult, IF(_xlpm.prefix="<", _xlpm.result/2, _xlpm.result), IF(_xlpm.adjResult > _xlpm.critValue, "Exceeds", "OK") ), "NOT FOUND") -> OK
A26: BH03 | B26: 2 - 2.1 | C26: 45245.625 | D26: Arsenic | F26: 6 | G26: mg/kg | H26: =IF( IF(E26="<",F26/2,F26) > VALUE(LEFT(_xlfn.XLOOKUP(D26,Criteria!A:A,Criteria!B:B),FIND(" ",_xlfn.XLOOKUP(D26,Criteria!A:A,Criteria!B:B))-1)), "Exceeds", "OK" ) -> OK | I26: =IFERROR( _xlfn.LET( _xlpm.chem, D26, _xlpm.prefix, E26, _xlpm.result, F26, _xlpm.mappedChem, _xlfn.XLOOKUP(_xlpm.chem, Map!A:A, Map!B:B), _xlpm.critText, _xlfn.XLOOKUP(_xlpm.mappedChem, Criteria!A:A, Criteria!B:B), _xlpm.critValue, VALUE(LEFT(_xlpm.critText, FIND(" ", _xlpm.critText)-1)), _xlpm.adjResult, IF(_xlpm.prefix="<", _xlpm.result/2, _xlpm.result), IF(_xlpm.adjResult > _xlpm.critValue, "Exceeds", "OK") ), "NOT FOUND") -> OK
A27: BH03 | B27: 2 - 2.1 | C27: 45245.625 | D27: Cadmium | E27: < | F27: 1 | G27: mg/kg | H27: =IF( IF(E27="<",F27/2,F27) > VALUE(LEFT(_xlfn.XLOOKUP(D27,Criteria!A:A,Criteria!B:B),FIND(" ",_xlfn.XLOOKUP(D27,Criteria!A:A,Criteria!B:B))-1)), "Exceeds", "OK" ) -> OK | I27: =IFERROR( _xlfn.LET( _xlpm.chem, D27, _xlpm.prefix, E27, _xlpm.result, F27, _xlpm.mappedChem, _xlfn.XLOOKUP(_xlpm.chem, Map!A:A, Map!B:B), _xlpm.critText, _xlfn.XLOOKUP(_xlpm.mappedChem, Criteria!A:A, Criteria!B:B), _xlpm.critValue, VALUE(LEFT(_xlpm.critText, FIND(" ", _xlpm.critText)-1)), _xlpm.adjResult, IF(_xlpm.prefix="<", _xlpm.result/2, _xlpm.result), IF(_xlpm.adjResult > _xlpm.critValue, "Exceeds", "OK") ), "NOT FOUND") -> OK
A28: BH03 | B28: 2 - 2.1 | C28: 45245.625 | D28: Chromium | F28: 28 | G28: mg/kg | H28: =IF( IF(E28="<",F28/2,F28) > VALUE(LEFT(_xlfn.XLOOKUP(D28,Criteria!A:A,Criteria!B:B),FIND(" ",_xlfn.XLOOKUP(D28,Criteria!A:A,Criteria!B:B))-1)), "Exceeds", "OK" ) -> #N/A | I28: =IFERROR( _xlfn.LET( _xlpm.chem, D28, _xlpm.prefix, E28, _xlpm.result, F28, _xlpm.mappedChem, _xlfn.XLOOKUP(_xlpm.chem, Map!A:A, Map!B:B), _xlpm.critText, _xlfn.XLOOKUP(_xlpm.mappedChem, Criteria!A:A, Criteria!B:B), _xlpm.critValue, VALUE(LEFT(_xlpm.critText, FIND(" ", _xlpm.critText)-1)), _xlpm.adjResult, IF(_xlpm.prefix="<", _xlpm.result/2, _xlpm.result), IF(_xlpm.adjResult > _xlpm.critValue, "Exceeds", "OK") ), "NOT FOUND") -> OK
A29: BH03 | B29: 2 - 2.1 | C29: 45245.625 | D29: Copper | F29: 49 | G29: mg/kg | H29: =IF( IF(E29="<",F29/2,F29) > VALUE(LEFT(_xlfn.XLOOKUP(D29,Criteria!A:A,Criteria!B:B),FIND(" ",_xlfn.XLOOKUP(D29,Criteria!A:A,Criteria!B:B))-1)), "Exceeds", "OK" ) -> OK | I29: =IFERROR( _xlfn.LET( _xlpm.chem, D29, _xlpm.prefix, E29, _xlpm.result, F29, _xlpm.mappedChem, _xlfn.XLOOKUP(_xlpm.chem, Map!A:A, Map!B:B), _xlpm.critText, _xlfn.XLOOKUP(_xlpm.mappedChem, Criteria!A:A, Criteria!B:B), _xlpm.critValue, VALUE(LEFT(_xlpm.critText, FIND(" ", _xlpm.critText)-1)), _xlpm.adjResult, IF(_xlpm.prefix="<", _xlpm.result/2, _xlpm.result), IF(_xlpm.adjResult > _xlpm.critValue, "Exceeds", "OK") ), "NOT FOUND") -> OK
A30: BH03 | B30: 2 - 2.1 | C30: 45245.625 | D30: Lead | F30: 184 | G30: mg/kg | H30: =IF( IF(E30="<",F30/2,F30) > VALUE(LEFT(_xlfn.XLOOKUP(D30,Criteria!A:A,Criteria!B:B),FIND(" ",_xlfn.XLOOKUP(D30,Criteria!A:A,Criteria!B:B))-1)), "Exceeds", "OK" ) -> OK | I30: =IFERROR( _xlfn.LET( _xlpm.chem, D30, _xlpm.prefix, E30, _xlpm.result, F30, _xlpm.mappedChem, _xlfn.XLOOKUP(_xlpm.chem, Map!A:A, Map!B:B), _xlpm.critText, _xlfn.XLOOKUP(_xlpm.mappedChem, Criteria!A:A, Criteria!B:B), _xlpm.critValue, VALUE(LEFT(_xlpm.critText, FIND(" ", _xlpm.critText)-1)), _xlpm.adjResult, IF(_xlpm.prefix="<", _xlpm.result/2, _xlpm.result), IF(_xlpm.adjResult > _xlpm.critValue, "Exceeds", "OK") ), "NOT FOUND") -> OK
A31: BH03 | B31: 2 - 2.1 | C31: 45245.625 | D31: Mercury | E31: < | F31: 0.1 | G31: mg/kg | H31: =IF( IF(E31="<",F31/2,F31) > VALUE(LEFT(_xlfn.XLOOKUP(D31,Criteria!A:A,Criteria!B:B),FIND(" ",_xlfn.XLOOKUP(D31,Criteria!A:A,Criteria!B:B))-1)), "Exceeds", "OK" ) -> OK | I31: =IFERROR( _xlfn.LET( _xlpm.chem, D31, _xlpm.prefix, E31, _xlpm.result, F31, _xlpm.mappedChem, _xlfn.XLOOKUP(_xlpm.chem, Map!A:A, Map!B:B), _xlpm.critText, _xlfn.XLOOKUP(_xlpm.mappedChem, Criteria!A:A, Criteria!B:B), _xlpm.critValue, VALUE(LEFT(_xlpm.critText, FIND(" ", _xlpm.critText)-1)), _xlpm.adjResult, IF(_xlpm.prefix="<", _xlpm.result/2, _xlpm.result), IF(_xlpm.adjResult > _xlpm.critValue, "Exceeds", "OK") ), "NOT FOUND") -> OK
A32: BH03 | B32: 2 - 2.1 | C32: 45245.625 | D32: Nickel | F32: 26 | G32: mg/kg | H32: =IF( IF(E32="<",F32/2,F32) > VALUE(LEFT(_xlfn.XLOOKUP(D32,Criteria!A:A,Criteria!B:B),FIND(" ",_xlfn.XLOOKUP(D32,Criteria!A:A,Criteria!B:B))-1)), "Exceeds", "OK" ) -> OK | I32: =IFERROR( _xlfn.LET( _xlpm.chem, D32, _xlpm.prefix, E32, _xlpm.result, F32, _xlpm.mappedChem, _xlfn.XLOOKUP(_xlpm.chem, Map!A:A, Map!B:B), _xlpm.critText, _xlfn.XLOOKUP(_xlpm.mappedChem, Criteria!A:A, Criteria!B:B), _xlpm.critValue, VALUE(LEFT(_xlpm.critText, FIND(" ", _xlpm.critText)-1)), _xlpm.adjResult, IF(_xlpm.prefix="<", _xlpm.result/2, _xlpm.result), IF(_xlpm.adjResult > _xlpm.critValue, "Exceeds", "OK") ), "NOT FOUND") -> OK
A33: BH03 | B33: 2 - 2.1 | C33: 45245.625 | D33: Zinc | F33: 225 | G33: mg/kg | H33: =IF( IF(E33="<",F33/2,F33) > VALUE(LEFT(_xlfn.XLOOKUP(D33,Criteria!A:A,Criteria!B:B),FIND(" ",_xlfn.XLOOKUP(D33,Criteria!A:A,Criteria!B:B))-1)), "Exceeds", "OK" ) -> OK | I33: =IFERROR( _xlfn.LET( _xlpm.chem, D33, _xlpm.prefix, E33, _xlpm.result, F33, _xlpm.mappedChem, _xlfn.XLOOKUP(_xlpm.chem, Map!A:A, Map!B:B), _xlpm.critText, _xlfn.XLOOKUP(_xlpm.mappedChem, Criteria!A:A, Criteria!B:B), _xlpm.critValue, VALUE(LEFT(_xlpm.critText, FIND(" ", _xlpm.critText)-1)), _xlpm.adjResult, IF(_xlpm.prefix="<", _xlpm.result/2, _xlpm.result), IF(_xlpm.adjResult > _xlpm.critValue, "Exceeds", "OK") ), "NOT FOUND") -> OK
A34: BH05 | B34: 1.8 - 1.9 | C34: 45245.625 | D34: Arsenic | F34: 5 | G34: mg/kg | H34: =IF( IF(E34="<",F34/2,F34) > VALUE(LEFT(_xlfn.XLOOKUP(D34,Criteria!A:A,Criteria!B:B),FIND(" ",_xlfn.XLOOKUP(D34,Criteria!A:A,Criteria!B:B))-1)), "Exceeds", "OK" ) -> OK | I34: =IFERROR( _xlfn.LET( _xlpm.chem, D34, _xlpm.prefix, E34, _xlpm.result, F34, _xlpm.mappedChem, _xlfn.XLOOKUP(_xlpm.chem, Map!A:A, Map!B:B), _xlpm.critText, _xlfn.XLOOKUP(_xlpm.mappedChem, Criteria!A:A, Criteria!B:B), _xlpm.critValue, VALUE(LEFT(_xlpm.critText, FIND(" ", _xlpm.critText)-1)), _xlpm.adjResult, IF(_xlpm.prefix="<", _xlpm.result/2, _xlpm.result), IF(_xlpm.adjResult > _xlpm.critValue, "Exceeds", "OK") ), "NOT FOUND") -> OK
A35: BH05 | B35: 1.8 - 1.9 | C35: 45245.625 | D35: Cadmium | E35: < | F35: 1 | G35: mg/kg | H35: =IF( IF(E35="<",F35/2,F35) > VALUE(LEFT(_xlfn.XLOOKUP(D35,Criteria!A:A,Criteria!B:B),FIND(" ",_xlfn.XLOOKUP(D35,Criteria!A:A,Criteria!B:B))-1)), "Exceeds", "OK" ) -> OK | I35: =IFERROR( _xlfn.LET( _xlpm.chem, D35, _xlpm.prefix, E35, _xlpm.result, F35, _xlpm.mappedChem, _xlfn.XLOOKUP(_xlpm.chem, Map!A:A, Map!B:B), _xlpm.critText, _xlfn.XLOOKUP(_xlpm.mappedChem, Criteria!A:A, Criteria!B:B), _xlpm.critValue, VALUE(LEFT(_xlpm.critText, FIND(" ", _xlpm.critText)-1)), _xlpm.adjResult, IF(_xlpm.prefix="<", _xlpm.result/2, _xlpm.result), IF(_xlpm.adjResult > _xlpm.critValue, "Exceeds", "OK") ), "NOT FOUND") -> OK
A36: BH05 | B36: 1.8 - 1.9 | C36: 45245.625 | D36: Chromium | F36: 56 | G36: mg/kg | H36: =IF( IF(E36="<",F36/2,F36) > VALUE(LEFT(_xlfn.XLOOKUP(D36,Criteria!A:A,Criteria!B:B),FIND(" ",_xlfn.XLOOKUP(D36,Criteria!A:A,Criteria!B:B))-1)), "Exceeds", "OK" ) -> #N/A | I36: =IFERROR( _xlfn.LET( _xlpm.chem, D36, _xlpm.prefix, E36, _xlpm.result, F36, _xlpm.mappedChem, _xlfn.XLOOKUP(_xlpm.chem, Map!A:A, Map!B:B), _xlpm.critText, _xlfn.XLOOKUP(_xlpm.mappedChem, Criteria!A:A, Criteria!B:B), _xlpm.critValue, VALUE(LEFT(_xlpm.critText, FIND(" ", _xlpm.critText)-1)), _xlpm.adjResult, IF(_xlpm.prefix="<", _xlpm.result/2, _xlpm.result), IF(_xlpm.adjResult > _xlpm.critValue, "Exceeds", "OK") ), "NOT FOUND") -> OK
A37: BH05 | B37: 1.8 - 1.9 | C37: 45245.625 | D37: Copper | F37: 22 | G37: mg/kg | H37: =IF( IF(E37="<",F37/2,F37) > VALUE(LEFT(_xlfn.XLOOKUP(D37,Criteria!A:A,Criteria!B:B),FIND(" ",_xlfn.XLOOKUP(D37,Criteria!A:A,Criteria!B:B))-1)), "Exceeds", "OK" ) -> OK | I37: =IFERROR( _xlfn.LET( _xlpm.chem, D37, _xlpm.prefix, E37, _xlpm.result, F37, _xlpm.mappedChem, _xlfn.XLOOKUP(_xlpm.chem, Map!A:A, Map!B:B), _xlpm.critText, _xlfn.XLOOKUP(_xlpm.mappedChem, Criteria!A:A, Criteria!B:B), _xlpm.critValue, VALUE(LEFT(_xlpm.critText, FIND(" ", _xlpm.critText)-1)), _xlpm.adjResult, IF(_xlpm.prefix="<", _xlpm.result/2, _xlpm.result), IF(_xlpm.adjResult > _xlpm.critValue, "Exceeds", "OK") ), "NOT FOUND") -> OK
A38: BH05 | B38: 1.8 - 1.9 | C38: 45245.625 | D38: Lead | F38: 26 | G38: mg/kg | H38: =IF( IF(E38="<",F38/2,F38) > VALUE(LEFT(_xlfn.XLOOKUP(D38,Criteria!A:A,Criteria!B:B),FIND(" ",_xlfn.XLOOKUP(D38,Criteria!A:A,Criteria!B:B))-1)), "Exceeds", "OK" ) -> OK | I38: =IFERROR( _xlfn.LET( _xlpm.chem, D38, _xlpm.prefix, E38, _xlpm.result, F38, _xlpm.mappedChem, _xlfn.XLOOKUP(_xlpm.chem, Map!A:A, Map!B:B), _xlpm.critText, _xlfn.XLOOKUP(_xlpm.mappedChem, Criteria!A:A, Criteria!B:B), _xlpm.critValue, VALUE(LEFT(_xlpm.critText, FIND(" ", _xlpm.critText)-1)), _xlpm.adjResult, IF(_xlpm.prefix="<", _xlpm.result/2, _xlpm.result), IF(_xlpm.adjResult > _xlpm.critValue, "Exceeds", "OK") ), "NOT FOUND") -> OK
A39: BH05 | B39: 1.8 - 1.9 | C39: 45245.625 | D39: Mercury | E39: < | F39: 0.1 | G39: mg/kg | H39: =IF( IF(E39="<",F39/2,F39) > VALUE(LEFT(_xlfn.XLOOKUP(D39,Criteria!A:A,Criteria!B:B),FIND(" ",_xlfn.XLOOKUP(D39,Criteria!A:A,Criteria!B:B))-1)), "Exceeds", "OK" ) -> OK | I39: =IFERROR( _xlfn.LET( _xlpm.chem, D39, _xlpm.prefix, E39, _xlpm.result, F39, _xlpm.mappedChem, _xlfn.XLOOKUP(_xlpm.chem, Map!A:A, Map!B:B), _xlpm.critText, _xlfn.XLOOKUP(_xlpm.mappedChem, Criteria!A:A, Criteria!B:B), _xlpm.critValue, VALUE(LEFT(_xlpm.critText, FIND(" ", _xlpm.critText)-1)), _xlpm.adjResult, IF(_xlpm.prefix="<", _xlpm.result/2, _xlpm.result), IF(_xlpm.adjResult > _xlpm.critValue, "Exceeds", "OK") ), "NOT FOUND") -> OK
A40: BH05 | B40: 1.8 - 1.9 | C40: 45245.625 | D40: Nickel | F40: 55 | G40: mg/kg | H40: =IF( IF(E40="<",F40/2,F40) > VALUE(LEFT(_xlfn.XLOOKUP(D40,Criteria!A:A,Criteria!B:B),FIND(" ",_xlfn.XLOOKUP(D40,Criteria!A:A,Criteria!B:B))-1)), "Exceeds", "OK" ) -> OK | I40: =IFERROR( _xlfn.LET( _xlpm.chem, D40, _xlpm.prefix, E40, _xlpm.result, F40, _xlpm.mappedChem, _xlfn.XLOOKUP(_xlpm.chem, Map!A:A, Map!B:B), _xlpm.critText, _xlfn.XLOOKUP(_xlpm.mappedChem, Criteria!A:A, Criteria!B:B), _xlpm.critValue, VALUE(LEFT(_xlpm.critText, FIND(" ", _xlpm.critText)-1)), _xlpm.adjResult, IF(_xlpm.prefix="<", _xlpm.result/2, _xlpm.result), IF(_xlpm.adjResult > _xlpm.critValue, "Exceeds", "OK") ), "NOT FOUND") -> OK
A41: BH05 | B41: 1.8 - 1.9 | C41: 45245.625 | D41: Zinc | F41: 344 | G41: mg/kg | H41: =IF( IF(E41="<",F41/2,F41) > VALUE(LEFT(_xlfn.XLOOKUP(D41,Criteria!A:A,Criteria!B:B),FIND(" ",_xlfn.XLOOKUP(D41,Criteria!A:A,Criteria!B:B))-1)), "Exceeds", "OK" ) -> OK | I41: =IFERROR( _xlfn.LET( _xlpm.chem, D41, _xlpm.prefix, E41, _xlpm.result, F41, _xlpm.mappedChem, _xlfn.XLOOKUP(_xlpm.chem, Map!A:A, Map!B:B), _xlpm.critText, _xlfn.XLOOKUP(_xlpm.mappedChem, Criteria!A:A, Criteria!B:B), _xlpm.critValue, VALUE(LEFT(_xlpm.critText, FIND(" ", _xlpm.critText)-1)), _xlpm.adjResult, IF(_xlpm.prefix="<", _xlpm.result/2, _xlpm.result), IF(_xlpm.adjResult > _xlpm.critValue, "Exceeds", "OK") ), "NOT FOUND") -> OK
A42: BH05 | B42: 5 - 5.1 | C42: 45245.625 | D42: Arsenic | F42: 12 | G42: mg/kg | H42: =IF( IF(E42="<",F42/2,F42) > VALUE(LEFT(_xlfn.XLOOKUP(D42,Criteria!A:A,Criteria!B:B),FIND(" ",_xlfn.XLOOKUP(D42,Criteria!A:A,Criteria!B:B))-1)), "Exceeds", "OK" ) -> OK | I42: =IFERROR( _xlfn.LET( _xlpm.chem, D42, _xlpm.prefix, E42, _xlpm.result, F42, _xlpm.mappedChem, _xlfn.XLOOKUP(_xlpm.chem, Map!A:A, Map!B:B), _xlpm.critText, _xlfn.XLOOKUP(_xlpm.mappedChem, Criteria!A:A, Criteria!B:B), _xlpm.critValue, VALUE(LEFT(_xlpm.critText, FIND(" ", _xlpm.critText)-1)), _xlpm.adjResult, IF(_xlpm.prefix="<", _xlpm.result/2, _xlpm.result), IF(_xlpm.adjResult > _xlpm.critValue, "Exceeds", "OK") ), "NOT FOUND") -> OK
A43: BH05 | B43: 5 - 5.1 | C43: 45245.625 | D43: Cadmium | F43: 2 | G43: mg/kg | H43: =IF( IF(E43="<",F43/2,F43) > VALUE(LEFT(_xlfn.XLOOKUP(D43,Criteria!A:A,Criteria!B:B),FIND(" ",_xlfn.XLOOKUP(D43,Criteria!A:A,Criteria!B:B))-1)), "Exceeds", "OK" ) -> OK | I43: =IFERROR( _xlfn.LET( _xlpm.chem, D43, _xlpm.prefix, E43, _xlpm.result, F43, _xlpm.mappedChem, _xlfn.XLOOKUP(_xlpm.chem, Map!A:A, Map!B:B), _xlpm.critText, _xlfn.XLOOKUP(_xlpm.mappedChem, Criteria!A:A, Criteria!B:B), _xlpm.critValue, VALUE(LEFT(_xlpm.critText, FIND(" ", _xlpm.critText)-1)), _xlpm.adjResult, IF(_xlpm.prefix="<", _xlpm.result/2, _xlpm.result), IF(_xlpm.adjResult > _xlpm.critValue, "Exceeds", "OK") ), "NOT FOUND") -> OK
A44: BH05 | B44: 5 - 5.1 | C44: 45245.625 | D44: Chromium | F44: 34 | G44: mg/kg | H44: =IF( IF(E44="<",F44/2,F44) > VALUE(LEFT(_xlfn.XLOOKUP(D44,Criteria!A:A,Criteria!B:B),FIND(" ",_xlfn.XLOOKUP(D44,Criteria!A:A,Criteria!B:B))-1)), "Exceeds", "OK" ) -> #N/A | I44: =IFERROR( _xlfn.LET( _xlpm.chem, D44, _xlpm.prefix, E44, _xlpm.result, F44, _xlpm.mappedChem, _xlfn.XLOOKUP(_xlpm.chem, Map!A:A, Map!B:B), _xlpm.critText, _xlfn.XLOOKUP(_xlpm.mappedChem, Criteria!A:A, Criteria!B:B), _xlpm.critValue, VALUE(LEFT(_xlpm.critText, FIND(" ", _xlpm.critText)-1)), _xlpm.adjResult, IF(_xlpm.prefix="<", _xlpm.result/2, _xlpm.result), IF(_xlpm.adjResult > _xlpm.critValue, "Exceeds", "OK") ), "NOT FOUND") -> OK
...

Sheet Map
A1: Result Name | B1: Criteria Name
A2: Chromium | B2: Chromium (total)
A3: Lead | B3: Lead
A4: Mercury | B4: Mercury
A5: Nickel | B5: Nickel
A6: Arsenic | B6: Arsenic
A7: Cadmium | B7: Cadmium
A8: Copper | B8: Copper
A9: Zinc | B9: Zinc

Sheet Exceed Summary
A3: Count of Criteria Formula 2 | B3: Column Labels
A4: Row Labels | B4: Exceeds | C4: Grand Total
A5: BH01 | B5: 5 | C5: 5
A6: 3 - 3.1 | B6: 4 | C6: 4
A7: 4.8 - 4.9 | B7: 1 | C7: 1
A8: BH05 | B8: 2 | C8: 2
A9: 5 - 5.1 | B9: 2 | C9: 2
A10: Grand Total | B10: 7 | C10: 7

Sheet Real Result
D3: Metals
D4: Arsenic | E4: Cadmium | F4: Chromium | G4: Copper | H4: Lead | I4: Mercury | J4: Nickel | K4: Zinc
D5: mg/kg | E5: mg/kg | F5: mg/kg | G5: mg/kg | H5: mg/kg | I5: mg/kg | J5: mg/kg | K5: mg/kg
A6: EQL | D6: 5 | E6: 1 | F6: 2 | G6: 5 | H6: 5 | I6: 0.1 | J6: 2 | K6: 5
A7: Human Health HILA - Residential | D7: 100 | E7: 20 | F7: 100 | G7: 6000 | H7: 300 | I7: 40 | J7: 400 | K7: 7400
A9: Location Code | B9: Date | C9: Depth
A10: BH01 | B10: 45245 | C10: 3 - 3.1 | D10: 45 | E10: 24 | F10: 615 | G10: 253 | H10: 1,800 | I10: 0.1 | J10: 694 | K10: 2,340
A11: BH01 | B11: 45245 | C11: 4.8 - 4.9 | D11: 26 | E11: 5 | F11: 50 | G11: 2,150 | H11: 837 | I11: 0.2 | J11: 88 | K11: 5,310
A12: BH03 | B12: 45245 | C12: 0.5 - 0.6 | D12: 11 | E12: <1 | F12: 42 | G12: 23 | H12: 22 | I12: <0.1 | J12: 37 | K12: 72
A13: BH03 | B13: 45245 | C13: 2 - 2.1 | D13: 6 | E13: <1 | F13: 28 | G13: 49 | H13: 184 | I13: <0.1 | J13: 26 | K13: 225
A14: BH05 | B14: 45245 | C14: 1.8 - 1.9 | D14: 5 | E14: <1 | F14: 56 | G14: 22 | H14: 26 | I14: <0.1 | J14: 55 | K14: 344
A15: BH05 | B15: 45245 | C15: 5 - 5.1 | D15: 12 | E15: 2 | F15: 34 | G15: 1,460 | H15: 557 | I15: <0.1 | J15: 80 | K15: 30,000
A16: BH05 | B16: 45245 | C16: 7.5 - 7.6 | D16: <5 | E16: <1 | F16: 52 | G16: 43 | H16: 68 | I16: <0.1 | J16: 79 | K16: 1,950
